<robot name="manipulator">

  <!-- Used for fixing robot to Gazebo 'base_link' -->
  <link name="world"/>

  <joint name="fixed" type="fixed">
    <parent link="world"/>
    <child link="base_link"/>
  </joint>

  <link name="base_link">
    <inertial>
      <origin xyz="-0.029 3.0957E-06 0.081458" rpy="0 0 0" />
      <mass value="1.404" />
      <inertia
        ixx="0.0018489"
        ixy="2.7417E-07"
        ixz="-0.0010428"
        iyy="0.0047182"
        iyz="1.219E-07"
        izz="0.0028693" />
    </inertial>
    <visual>
      <origin xyz="0 0 0" rpy="0 0 0" />
      <geometry>
        <mesh filename="package://manipulator/meshes/base_link.STL" />
      </geometry>
      <material name="">
        <color rgba="0.89804 0.91765 0.92941 1" />
      </material>
    </visual>
    <collision>
      <origin xyz="0 0 0" rpy="0 0 0" />
      <geometry>
        <mesh filename="package://manipulator/meshes/base_link.STL" />
      </geometry>
    </collision>
  </link>

 <link name="shoulder_link">
    <inertial>
      <origin xyz="-0.024603 0.0034265 0.064143" rpy="0 0 0" />
      <mass value="4.1214" />
      <inertia
        ixx="0.0033788"
        ixy="-0.00012922"
        ixz="-0.00014319"
        iyy="0.0069305"
        iyz="0.00013755"
        izz="0.0071412" />
    </inertial>
    <visual>
      <origin xyz="0 0 0" rpy="0 0 0" />
      <geometry>
        <mesh filename="package://manipulator/meshes/shoulder_link.STL" />
      </geometry>
      <material name="">
        <color rgba="0.4 0.8 1.0 1" />
      </material>
    </visual>
    <collision>
      <origin xyz="0 0 0" rpy="0 0 0" />
      <geometry>
        <mesh filename="package://manipulator/meshes/shoulder_link.STL" />
      </geometry>
    </collision>
  </link>

  <joint name="shoulder_rotation" type="revolute">
    <origin xyz="0 0 0.13" rpy="0 0 0" />
    <parent link="base_link" />
    <child link="shoulder_link" />
    <axis xyz="0 0 1" />
    <limit
      lower="-3.14"
      upper="3.14"
      effort="50"
      velocity="8.3776" />
  </joint>

  <transmission name="shoulder_rotation_transmission">
    <type>transmission_interface/SimpleTransmission</type>
    <joint name="shoulder_rotation">
      <hardwareInterface>hardware_interface/VelocityJointInterface</hardwareInterface>
    </joint>
    <actuator name="shoulder_rotation_motor">
      <mechanicalReduction>1.5</mechanicalReduction>
      <hardwareInterface>hardware_interface/VelocityJointInterface</hardwareInterface>
    </actuator>
  </transmission>

  <link name="forearm_link">
    <inertial>
      <origin xyz="-0.030709 0.2846 0.0021162" rpy="0 0 0" />
      <mass value="2.138" />
      <inertia
        ixx="0.025172"
        ixy="-0.002607"
        ixz="-0.00013892"
        iyy="0.0043441"
        iyz="-0.00060463"
        izz="0.026065" />
    </inertial>
    <visual>
      <origin xyz="0 0 0" rpy="0 0 0" />
      <geometry>
        <mesh filename="package://manipulator/meshes/forearm_link.STL" />
      </geometry>
      <material name="">
        <color rgba="0.89804 0.91765 0.92941 1" />
      </material>
    </visual>
    <collision>
      <origin xyz="0 0 0" rpy="0 0 0" />
      <geometry>
        <mesh filename="package://manipulator/meshes/forearm_link.STL" />
      </geometry>
    </collision>
  </link>

  <joint name="forearm_rotation"
    type="revolute">
    <origin xyz="0 0.00175 0.0705" rpy="1.5708 0 0" />
    <parent link="shoulder_link" />
    <child link="forearm_link" />
    <axis xyz="0 0 -1" />
    <limit
      lower="-0.90"
      upper="1.3963"
      effort="500"
      velocity="1.2" />
  </joint>

  <transmission name="forearm_rotation_transmission">
      <type>transmission_interface/SimpleTransmission</type>
      <joint name="forearm_rotation">
        <hardwareInterface>hardware_interface/VelocityJointInterface</hardwareInterface>
      </joint>
      <actuator name="forearm_rotation_motor">
        <mechanicalReduction>157</mechanicalReduction>
        <hardwareInterface>hardware_interface/VelocityJointInterface</hardwareInterface>
      </actuator>
   </transmission>

  <link name="arm_link">
    <inertial>
      <origin xyz="0.1767 0.0069722 5.0223E-06" rpy="0 0 0" />
      <mass value="1.1195" />
      <inertia
        ixx="0.00045953"
        ixy="-4.6934E-05"
        ixz="1.8433E-06"
        iyy="0.023018"
        iyz="1.4945E-07"
        izz="0.022579" />
    </inertial>
    <visual>
      <origin xyz="0 0 0" rpy="0 0 0" />
      <geometry>
        <mesh filename="package://manipulator/meshes/arm_link.STL" />
      </geometry>
      <material
        name="">
        <color rgba="0.52941 0.54902 0.54902 1" />
      </material>
    </visual>
    <collision>
      <origin xyz="0 0 0" rpy="0 0 0" />
      <geometry>
        <mesh filename="package://manipulator/meshes/arm_link.STL" />
      </geometry>
    </collision>
  </link>

  <joint name="arm_rotation" type="revolute">
    <origin xyz="0 0.6 0" rpy="0 0 -1.3089" />
    <parent link="forearm_link" />
    <child link="arm_link" />
    <axis xyz="0 0 -1" />
    <limit
      lower="-2.5"
      upper="0"
      effort="500"
      velocity="0.2" />
  </joint>

  <transmission name="arm_rotation_transmission">
      <type>transmission_interface/SimpleTransmission</type>
      <joint name="arm_rotation">
        <hardwareInterface>hardware_interface/VelocityJointInterface</hardwareInterface>
      </joint>
      <actuator name="arm_rotation_motor">
        <mechanicalReduction>1</mechanicalReduction>
        <hardwareInterface>hardware_interface/VelocityJointInterface</hardwareInterface>
      </actuator>
   </transmission>

  <link name="wrist_rotation_link">
    <inertial>
      <origin xyz="0.00022986 -0.0044455 0.068045" rpy="0 0 0" />
      <mass value="0.70662" />
      <inertia
        ixx="0.00073736"
        ixy="-5.029E-05"
        ixz="-2.7832E-06"
        iyy="0.00091775"
        iyz="5.4552E-05"
        izz="0.0012144" />
    </inertial>
    <visual>
      <origin xyz="0 0 0" rpy="0 0 0" />
      <geometry>
        <mesh filename="package://manipulator/meshes/wrist_rotation_link.STL" />
      </geometry>
      <material name="">
        <color rgba="0.9 0.72 0 1" />
      </material>
    </visual>
    <collision>
      <origin xyz="0 0 0" rpy="0 0 0" />
      <geometry>
        <mesh filename="package://manipulator/meshes/wrist_rotation_link.STL" />
      </geometry>
    </collision>
  </link>

  <joint name="wrist_rotation" type="revolute">
    <origin xyz="0.408 0.005 0" rpy="0 1.5708 0" />
    <parent link="arm_link" />
    <child link="wrist_rotation_link" />
    <axis xyz="0 0 -1" />
    <limit
      lower="-3.14"
      upper="3.14"
      effort="18"
      velocity="8.3776" />
  </joint>

 <transmission name="wrist_rotation_transmission">
      <type>transmission_interface/SimpleTransmission</type>
      <joint name="wrist_rotation">
        <hardwareInterface>hardware_interface/VelocityJointInterface</hardwareInterface>
      </joint>
      <actuator name="wrist_rotation_motor">
        <mechanicalReduction>1</mechanicalReduction>
        <hardwareInterface>hardware_interface/VelocityJointInterface</hardwareInterface>
      </actuator>
  </transmission>

  <link name="wrist_pitch_link">
    <inertial>
      <origin xyz="0.02283 1.6924E-05 4.4001E-05" rpy="0 0 0" />
      <mass value="0.22279" />
      <inertia
        ixx="8.4052E-05"
        ixy="8.7929E-08"
        ixz="-3.0476E-07"
        iyy="0.00016875"
        iyz="4.7854E-08"
        izz="8.4698E-05" />
    </inertial>
    <visual>
      <origin xyz="0 0 0" rpy="0 0 0" />
      <geometry>
        <mesh filename="package://manipulator/meshes/wrist_pitch_link.STL" />
      </geometry>
      <material name="">
        <color rgba="0.6 0.8 0 1" />
      </material>
    </visual>
    <collision>
      <origin xyz="0 0 0" rpy="0 0 0" />
      <geometry>
        <mesh filename="package://manipulator/meshes/wrist_pitch_link.STL" />
      </geometry>
    </collision>
  </link>

  <joint
    name="wrist_pitch"
    type="revolute">
    <origin xyz="0 0 0.129" rpy="-1.5708 0 1.603" />
    <parent link="wrist_rotation_link" />
    <child link="wrist_pitch_link" />
    <axis xyz="0 0 -1" />
    <limit
      lower="0"
      upper="3.14"
      effort="10.8"
      velocity="5.236" />
  </joint>

 <link name="gripper_link">
    <inertial>
      <origin xyz="0.00062878 0.0062787 0.096632" rpy="0 0 0" />
      <mass value="0.52227" />
      <inertia
        ixx="0.0022506"
        ixy="-1.61E-06"
        ixz="-2.3088E-05"
        iyy="0.0026696"
        iyz="0.00015523"
        izz="0.00081423" />
    </inertial>
    <visual>
      <origin xyz="0 0 0" rpy="0 0 0" />
      <geometry>
        <mesh filename="package://manipulator/meshes/gripper_link.STL" />
      </geometry>
      <material name="">
        <color rgba="0.8 0.2 0.0 1" />
      </material>
    </visual>
    <collision>
      <origin xyz="0 0 0" rpy="0 0 0" />
      <geometry>
        <mesh filename="package://manipulator/meshes/gripper_link.STL" />
      </geometry>
    </collision>
  </link>

  <joint
    name="gripper_rotation"
    type="revolute">
    <origin xyz="0.0643 0 0" rpy="0 1.5708 0" />
    <parent link="wrist_pitch_link" />
    <child link="gripper_link" />
    <axis xyz="0 0 -1" />
    <limit
      lower="-3.14"
      upper="3.14"
      effort="10.8"
      velocity="5.236" />
  </joint>

  <transmission name="wrist_pitch_transmission">
      <type>transmission_interface/SimpleTransmission</type>
      <actuator name="wrist_pitch_motor">
        <mechanicalReduction>1.2</mechanicalReduction>
        <hardwareInterface>hardware_interface/VelocityJointInterface</hardwareInterface>
      </actuator>
      <joint name="wrist_pitch">
        <hardwareInterface>hardware_interface/VelocityJointInterface</hardwareInterface>
      </joint>
  </transmission>

  <transmission name="gripper_rotation_transmission">
        <type>transmission_interface/SimpleTransmission</type>
        <actuator name="gripper_rotation_motor">
          <mechanicalReduction>1.2</mechanicalReduction>
          <hardwareInterface>hardware_interface/VelocityJointInterface</hardwareInterface>
        </actuator>
        <joint name="gripper_rotation">
          <hardwareInterface>hardware_interface/VelocityJointInterface</hardwareInterface>
        </joint>
  </transmission>


  <!-- Gazebo definitions -->

    <gazebo>
      <self_collide>true</self_collide>

    </gazebo>

    <gazebo reference="base_link">
      <material>Gazebo/White</material>
      <gravity>true</gravity>
      <kp>1000000.0</kp>
      <kd>100.0</kd>
      <mu1>30.0</mu1>
      <mu2>30.0</mu2>
      <maxVel>1.0</maxVel>
      <minDepth>0.001</minDepth>
    </gazebo>

    <gazebo reference="shoulder_link">
      <material>Gazebo/Blue</material>
      <gravity>true</gravity>
      <kp>1000000.0</kp>
      <kd>100.0</kd>
      <mu1>0.6</mu1>
      <mu2>0.6</mu2>
      <minDepth>0.001</minDepth>
    </gazebo>

    <gazebo reference="forearm_link">
      <material>Gazebo/White</material>
      <gravity>true</gravity>
      <kp>1000000.0</kp>
      <kd>100.0</kd>
      <mu1>0.6</mu1>
      <mu2>0.6</mu2>
      <minDepth>0.001</minDepth>
    </gazebo>

    <gazebo reference="arm_link">
      <material>Gazebo/Gray</material>
      <gravity>true</gravity>
      <kp>1000000.0</kp>
      <kd>100.0</kd>
      <mu1>0.6</mu1>
      <mu2>0.6</mu2>
      <minDepth>0.001</minDepth>
    </gazebo>

    <gazebo reference="wrist_rotation_link">
      <material>Gazebo/Orange</material>
      <gravity>true</gravity>
      <kp>1000000.0</kp>
      <kd>100.0</kd>
      <mu1>0.6</mu1>
      <mu2>0.6</mu2>
      <minDepth>0.001</minDepth>
    </gazebo>

    <gazebo reference="wrist_pitch_link">
      <material>Gazebo/Green</material>
      <gravity>true</gravity>
      <kp>1000000.0</kp>
      <kd>100.0</kd>
      <mu1>0.6</mu1>
      <mu2>0.6</mu2>
      <minDepth>0.001</minDepth>
    </gazebo>

    <gazebo reference="gripper_link">
      <material>Gazebo/Red</material>
      <gravity>true</gravity>
      <kp>1000000.0</kp>
      <kd>100.0</kd>
      <mu1>0.6</mu1>
      <mu2>0.6</mu2>
      <minDepth>0.001</minDepth>
    </gazebo>

    <gazebo>
      <plugin name="gazebo_ros_control" filename="libgazebo_ros_control.so">
        <robotNamespace>/manipulator</robotNamespace>
        <robotParam>robot_description</robotParam>
      </plugin>
    </gazebo>

</robot>
